<?xml version="1.0" ?>
<!-- =================================================================================== -->
<!-- |    This document was autogenerated by xacro from /home/delta/ht_ws/src/techman_husky/urdf/test.xacro | -->
<!-- |    EDITING THIS FILE BY HAND IS NOT RECOMMENDED                                 | -->
<!-- =================================================================================== -->
<robot name="tmhus">
    <material name="dark_grey">
        <color rgba="0.2 0.2 0.2 1.0" />
    </material>
    <material name="medium_grey">
        <color rgba="0.6 0.6 0.6 1.0" />
    </material>
    <material name="light_grey">
        <color rgba="0.8 0.8 0.8 1.0" />
    </material>
    <material name="yellow">
        <color rgba="0.8 0.8 0.0 1.0" />
    </material>
    <material name="black">
        <color rgba="0.15 0.15 0.15 1.0" />
    </material>
    <material name="white">
        <color rgba="1.0 1.0 1.0 1.0" />
    </material>
    <material name="red">
        <color rgba="1.0 0.0 0.0 1.0" />
    </material>
    <!-- Base link is the center of the robot's bottom plate -->
    <link name="base_link">
        <visual>
            <origin rpy="0 0 0" xyz="0 0 0" />
            <geometry>
                <mesh filename="package://husky_description/meshes/base_link.dae" />
            </geometry>
        </visual>
        <collision>
            <origin rpy="0 0 0" xyz="0.0 0 0.061875" />
            <geometry>
                <box size="0.9874 0.5709 0.12375" />
            </geometry>
        </collision>
        <collision>
            <origin rpy="0 0 0" xyz="0 0 0.17562499999999998" />
            <geometry>
                <box size="0.7899200000000001 0.5709 0.10375" />
            </geometry>
        </collision>
        <inertial>
            <mass value="0.1" />
            <origin xyz="0 0 0" rpy="0 0 0" />
            <inertia ixx="0.03" iyy="0.03" izz="0.03" ixy="0.0" ixz="0.0" iyz="0.0" />
        </inertial>
    </link>
    <!-- Base footprint is on the ground under the robot -->
    <link name="base_footprint" />
    <joint name="base_footprint_joint" type="fixed">
        <origin rpy="0 0 0" xyz="0 0 -0.13228" />
        <parent link="base_link" />
        <child link="base_footprint" />
    </joint>
    <!-- Inertial link stores the robot's inertial information -->
    <link name="inertial_link">
        <inertial>
            <mass value="46.034" />
            <origin xyz="-0.00065 -0.085 0.062" />
            <inertia ixx="0.6022" ixy="-0.02364" ixz="-0.1197" iyy="1.7386" iyz="-0.001544" izz="2.0296" />
        </inertial>
    </link>
    <joint name="inertial_joint" type="fixed">
        <origin rpy="0 0 0" xyz="0 0 0" />
        <parent link="base_link" />
        <child link="inertial_link" />
    </joint>
    <link name="front_left_wheel_link">
        <inertial>
            <mass value="2.637" />
            <origin xyz="0 0 0" rpy="0 0 0" />
            <inertia ixx="0.02467" ixy="0" ixz="0" iyy="0.04411" iyz="0" izz="0.02467" />
        </inertial>
        <visual>
            <origin rpy="0 0 0" xyz="0 0 0" />
            <geometry>
                <mesh filename="package://husky_description/meshes/wheel.dae" />
            </geometry>
        </visual>
        <collision>
            <origin rpy="1.570795 0 0" xyz="0 0 0" />
            <geometry>
                <cylinder length="0.1143" radius="0.1651" />
            </geometry>
        </collision>
    </link>
    <gazebo reference="front_left_wheel_link">
        <mu1 value="1.0" />
        <mu2 value="1.0" />
        <kp value="10000000.0" />
        <kd value="1.0" />
        <fdir1 value="1 0 0" />
        <plugin name="gazebo_ros_control">
            <robotNamespace>/</robotNamespace>
        </plugin>
    </gazebo>
    <joint name="front_left_wheel" type="continuous">
        <parent link="base_link" />
        <child link="front_left_wheel_link" />
        <origin rpy="0 0 0" xyz="0.256 0.2854 0.03282" />
        <axis rpy="0 0 0" xyz="0 1 0" />
    </joint>
    <transmission name="front_left_wheel_trans" type="SimpleTransmission">
        <type>transmission_interface/SimpleTransmission</type>
        <actuator name="front_left_wheel_motor">
            <mechanicalReduction>1</mechanicalReduction>
            <hardwareInterface>hardware_interface/PositionJointInterface</hardwareInterface>
        </actuator>
        <joint name="front_left_wheel">
            <hardwareInterface>hardware_interface/VelocityJointInterface</hardwareInterface>
        </joint>
    </transmission>
    <link name="front_right_wheel_link">
        <inertial>
            <mass value="2.637" />
            <origin xyz="0 0 0" rpy="0 0 0" />
            <inertia ixx="0.02467" ixy="0" ixz="0" iyy="0.04411" iyz="0" izz="0.02467" />
        </inertial>
        <visual>
            <origin rpy="0 0 0" xyz="0 0 0" />
            <geometry>
                <mesh filename="package://husky_description/meshes/wheel.dae" />
            </geometry>
        </visual>
        <collision>
            <origin rpy="1.570795 0 0" xyz="0 0 0" />
            <geometry>
                <cylinder length="0.1143" radius="0.1651" />
            </geometry>
        </collision>
    </link>
    <gazebo reference="front_right_wheel_link">
        <mu1 value="1.0" />
        <mu2 value="1.0" />
        <kp value="10000000.0" />
        <kd value="1.0" />
        <fdir1 value="1 0 0" />
    </gazebo>
    <joint name="front_right_wheel" type="continuous">
        <parent link="base_link" />
        <child link="front_right_wheel_link" />
        <origin rpy="0 0 0" xyz="0.256 -0.2854 0.03282" />
        <axis rpy="0 0 0" xyz="0 1 0" />
    </joint>
    <transmission name="front_right_wheel_trans" type="SimpleTransmission">
        <type>transmission_interface/SimpleTransmission</type>
        <actuator name="front_right_wheel_motor">
            <mechanicalReduction>1</mechanicalReduction>
            <hardwareInterface>hardware_interface/PositionJointInterface</hardwareInterface>
        </actuator>
        <joint name="front_right_wheel">
            <hardwareInterface>hardware_interface/VelocityJointInterface</hardwareInterface>
        </joint>
    </transmission>
    <link name="rear_left_wheel_link">
        <inertial>
            <mass value="2.637" />
            <origin xyz="0 0 0" rpy="0 0 0" />
            <inertia ixx="0.02467" ixy="0" ixz="0" iyy="0.04411" iyz="0" izz="0.02467" />
        </inertial>
        <visual>
            <origin rpy="0 0 0" xyz="0 0 0" />
            <geometry>
                <mesh filename="package://husky_description/meshes/wheel.dae" />
            </geometry>
        </visual>
        <collision>
            <origin rpy="1.570795 0 0" xyz="0 0 0" />
            <geometry>
                <cylinder length="0.1143" radius="0.1651" />
            </geometry>
        </collision>
    </link>
    <gazebo reference="rear_left_wheel_link">
        <mu1 value="1.0" />
        <mu2 value="1.0" />
        <kp value="10000000.0" />
        <kd value="1.0" />
        <fdir1 value="1 0 0" />
    </gazebo>
    <joint name="rear_left_wheel" type="continuous">
        <parent link="base_link" />
        <child link="rear_left_wheel_link" />
        <origin rpy="0 0 0" xyz="-0.256 0.2854 0.03282" />
        <axis rpy="0 0 0" xyz="0 1 0" />
    </joint>
    <transmission name="rear_left_wheel_trans" type="SimpleTransmission">
        <type>transmission_interface/SimpleTransmission</type>
        <actuator name="rear_left_wheel_motor">
            <mechanicalReduction>1</mechanicalReduction>
            <hardwareInterface>hardware_interface/PositionJointInterface</hardwareInterface>
        </actuator>
        <joint name="rear_left_wheel">
            <hardwareInterface>hardware_interface/VelocityJointInterface</hardwareInterface>
        </joint>
    </transmission>
    <link name="rear_right_wheel_link">
        <inertial>
            <mass value="2.637" />
            <origin xyz="0 0 0" rpy="0 0 0" />
            <inertia ixx="0.02467" ixy="0" ixz="0" iyy="0.04411" iyz="0" izz="0.02467" />
        </inertial>
        <visual>
            <origin rpy="0 0 0" xyz="0 0 0" />
            <geometry>
                <mesh filename="package://husky_description/meshes/wheel.dae" />
            </geometry>
        </visual>
        <collision>
            <origin rpy="1.570795 0 0" xyz="0 0 0" />
            <geometry>
                <cylinder length="0.1143" radius="0.1651" />
            </geometry>
        </collision>
    </link>
    <gazebo reference="rear_right_wheel_link">
        <mu1 value="1.0" />
        <mu2 value="1.0" />
        <kp value="10000000.0" />
        <kd value="1.0" />
        <fdir1 value="1 0 0" />
    </gazebo>
    <joint name="rear_right_wheel" type="continuous">
        <parent link="base_link" />
        <child link="rear_right_wheel_link" />
        <origin rpy="0 0 0" xyz="-0.256 -0.2854 0.03282" />
        <axis rpy="0 0 0" xyz="0 1 0" />
    </joint>
    <transmission name="rear_right_wheel_trans" type="SimpleTransmission">
        <type>transmission_interface/SimpleTransmission</type>
        <actuator name="rear_right_wheel_motor">
            <mechanicalReduction>1</mechanicalReduction>
            <hardwareInterface>hardware_interface/PositionJointInterface</hardwareInterface>
        </actuator>
        <joint name="rear_right_wheel">
            <hardwareInterface>hardware_interface/VelocityJointInterface</hardwareInterface>
        </joint>
    </transmission>
    <!--
      CHASSIS: Spawn and attach default chassis.
               Currently, no customization available.
    -->
    <!-- Spawn Husky chassis -->
    <link name="top_chassis_link">
        <visual>
            <origin rpy="0 0 0" xyz="0 0 0" />
            <geometry>
                <mesh filename="package://husky_description/meshes/top_chassis.dae" />
            </geometry>
        </visual>
    </link>
    <!-- Attach chassis to the robot -->
    <joint name="top_chassis_joint" type="fixed">
        <parent link="base_link" />
        <child link="top_chassis_link" />
    </joint>
    <link name="front_bumper_link">
        <visual>
            <geometry>
                <mesh filename="package://husky_description/meshes/bumper.dae" />
            </geometry>
        </visual>
    </link>
    <!-- Attach front bumper -->
    <joint name="front_bumper" type="fixed">
        <origin rpy="0 0 0" xyz="0.48 0 0.091" />
        <parent link="base_link" />
        <child link="front_bumper_link" />
    </joint>
    <link name="rear_bumper_link">
        <visual>
            <geometry>
                <mesh filename="package://husky_description/meshes/bumper.dae" />
            </geometry>
        </visual>
    </link>
    <!-- Attach rear bumper -->
    <joint name="rear_bumper" type="fixed">
        <origin rpy="0 0 3.14159" xyz="-0.48 0 0.091" />
        <parent link="base_link" />
        <child link="rear_bumper_link" />
    </joint>
    <!-- Spawn user rails -->
    <link name="user_rail_link">
        <visual>
            <geometry>
                <mesh filename="package://husky_description/meshes/user_rail.dae" />
            </geometry>
        </visual>
    </link>
    <!-- Attach user rails to base link -->
    <joint name="user_rail" type="fixed">
        <origin rpy="0 0 0" xyz="0.272 0 0.245" />
        <parent link="base_link" />
        <child link="user_rail_link" />
    </joint>
    <!-- Spawn default top plate -->
    <link name="top_plate_link">
        <visual>
            <origin rpy="0 0 0" xyz="0 0 0" />
            <geometry>
                <mesh filename="package://husky_description/meshes/top_plate.dae" />
            </geometry>
        </visual>
        <collision>
            <origin rpy="0 0 0" xyz="0 0 0" />
            <geometry>
                <mesh filename="package://husky_description/meshes/top_plate.stl" />
            </geometry>
        </collision>
        <inertial>
            <mass value="0.1" />
            <origin xyz="0 0 0" rpy="0 0 0" />
            <inertia ixx="0.03" iyy="0.03" izz="0.03" ixy="0.0" ixz="0.0" iyz="0.0" />
        </inertial>
    </link>
    <!-- Attach default top plate -->
    <joint name="top_plate_joint" type="fixed">
        <parent link="base_link" />
        <child link="top_plate_link" />
        <origin rpy="0 0 0" xyz="0.0812 0 0.245" />
    </joint>
    <!-- Default top plate front link -->
    <link name="top_plate_front_link" />
    <joint name="top_plate_front_joint" type="fixed">
        <parent link="top_plate_link" />
        <child link="top_plate_front_link" />
        <origin rpy="0 0 0" xyz="0.36367 0 0.00639" />
    </joint>
    <!-- Default top plate rear link-->
    <link name="top_plate_rear_link" />
    <joint name="top_plate_rear_joint" type="fixed">
        <parent link="top_plate_link" />
        <child link="top_plate_rear_link" />
        <origin rpy="0 0 0" xyz="-0.36633 0 0.00639" />
    </joint>
    <!--
      IMU Link: Standard location to add an IMU (i.e. UM7 or Microstrain)
  -->
    <link name="imu_link" />
    <joint name="imu_joint" type="fixed">
        <origin rpy="0 -1.5708 3.1416" xyz="0.19 0 0.149" />
        <parent link="base_link" />
        <child link="imu_link" />
    </joint>
    <gazebo reference="imu_link" />
    <!-- BlackflyS Camera Primary and Secondary -->
    <gazebo>
        <plugin filename="libgazebo_ros_control.so" name="gazebo_ros_control">
            <robotNamespace>/</robotNamespace>
            <legacyModeNS>true</legacyModeNS>
        </plugin>
    </gazebo>
    <gazebo>
        <plugin filename="libhector_gazebo_ros_imu.so" name="imu_controller">
            <robotNamespace>/</robotNamespace>
            <updateRate>50.0</updateRate>
            <bodyName>base_link</bodyName>
            <topicName>imu/data</topicName>
            <accelDrift>0.005 0.005 0.005</accelDrift>
            <accelGaussianNoise>0.005 0.005 0.005</accelGaussianNoise>
            <rateDrift>0.005 0.005 0.005</rateDrift>
            <rateGaussianNoise>0.005 0.005 0.005</rateGaussianNoise>
            <headingDrift>0.005</headingDrift>
            <headingGaussianNoise>0.005</headingGaussianNoise>
        </plugin>
    </gazebo>
    <gazebo>
        <plugin filename="libhector_gazebo_ros_gps.so" name="gps_controller">
            <robotNamespace>/</robotNamespace>
            <updateRate>40</updateRate>
            <bodyName>base_link</bodyName>
            <frameId>base_link</frameId>
            <topicName>navsat/fix</topicName>
            <velocityTopicName>navsat/vel</velocityTopicName>
            <referenceLatitude>49.9</referenceLatitude>
            <referenceLongitude>8.9</referenceLongitude>
            <referenceHeading>0</referenceHeading>
            <referenceAltitude>0</referenceAltitude>
            <drift>0.0001 0.0001 0.0001</drift>
        </plugin>
    </gazebo>
    <!-- This file is a placeholder which is included by default from
       husky.urdf.xacro. If a robot is being customized and requires
       additional URDF, set the HUSKY_URDF_EXTRAS environment variable
       to the full path of the file you would like included. -->
    <!-- This file is a placeholder which is included by default from
       husky.urdf.xacro. If a robot is being customized and requires
       additional URDF, set the HUSKY_URDF_EXTRAS environment variable
       to the full path of the file you would like included. -->
    <gazebo reference="link_1">
        <selfCollide>true</selfCollide>
    </gazebo>
    <gazebo reference="link_2">
        <selfCollide>true</selfCollide>
    </gazebo>
    <gazebo reference="link_3">
        <selfCollide>true</selfCollide>
    </gazebo>
    <gazebo reference="link_4">
        <selfCollide>true</selfCollide>
    </gazebo>
    <gazebo reference="link_5">
        <selfCollide>true</selfCollide>
    </gazebo>
    <gazebo reference="link_6">
        <selfCollide>true</selfCollide>
    </gazebo>
    <gazebo>
        <plugin filename="libgazebo_ros_control.so" name="gazebo_ros_control">
            <robotNamespace>/</robotNamespace>
            <robotSimType>gazebo_ros_control/DefaultRobotHWSim</robotSimType>
        </plugin>
    </gazebo>
    <transmission name="trans_1">
        <type>transmission_interface/SimpleTransmission</type>
        <joint name="shoulder_1_joint">
            <hardwareInterface>hardware_interface/PositionJointInterface</hardwareInterface>
        </joint>
        <actuator name="motor_1">
            <mechanicalReduction>1</mechanicalReduction>
            <hardwareInterface>hardware_interface/PositionJointInterface</hardwareInterface>
        </actuator>
    </transmission>
    <transmission name="trans_2">
        <type>transmission_interface/SimpleTransmission</type>
        <joint name="shoulder_2_joint">
            <hardwareInterface>hardware_interface/PositionJointInterface</hardwareInterface>
        </joint>
        <actuator name="motor_2">
            <mechanicalReduction>1</mechanicalReduction>
            <hardwareInterface>hardware_interface/PositionJointInterface</hardwareInterface>
        </actuator>
    </transmission>
    <transmission name="trans_3">
        <type>transmission_interface/SimpleTransmission</type>
        <joint name="elbow_joint">
            <hardwareInterface>hardware_interface/PositionJointInterface</hardwareInterface>
        </joint>
        <actuator name="motor_3">
            <mechanicalReduction>1</mechanicalReduction>
            <hardwareInterface>hardware_interface/PositionJointInterface</hardwareInterface>
        </actuator>
    </transmission>
    <transmission name="trans_4">
        <type>transmission_interface/SimpleTransmission</type>
        <joint name="wrist_1_joint">
            <hardwareInterface>hardware_interface/PositionJointInterface</hardwareInterface>
        </joint>
        <actuator name="motor_4">
            <mechanicalReduction>1</mechanicalReduction>
            <hardwareInterface>hardware_interface/PositionJointInterface</hardwareInterface>
        </actuator>
    </transmission>
    <transmission name="trans_5">
        <type>transmission_interface/SimpleTransmission</type>
        <joint name="wrist_2_joint">
            <hardwareInterface>hardware_interface/PositionJointInterface</hardwareInterface>
        </joint>
        <actuator name="motor_5">
            <mechanicalReduction>1</mechanicalReduction>
            <hardwareInterface>hardware_interface/PositionJointInterface</hardwareInterface>
        </actuator>
    </transmission>
    <transmission name="trans_6">
        <type>transmission_interface/SimpleTransmission</type>
        <joint name="wrist_3_joint">
            <hardwareInterface>hardware_interface/PositionJointInterface</hardwareInterface>
        </joint>
        <actuator name="motor_6">
            <mechanicalReduction>1</mechanicalReduction>
            <hardwareInterface>hardware_interface/PositionJointInterface</hardwareInterface>
        </actuator>
    </transmission>
    <material name="none">
        <color rgba="0.0 0.0 0.0 1.0" />
    </material>
    <material name="lightgrey">
        <color rgba="0.5 0.5 0.5 1.0" />
    </material>
    <material name="grey">
        <color rgba="0.75 0.75 0.75 1.0" />
    </material>
    <material name="whitew">
        <color rgba="0.95 0.95 0.95 1.0" />
    </material>
    <material name="redw">
        <color rgba="0.95 0.0 0.0 1.0" />
    </material>
    <material name="orangew">
        <color rgba="1.0 0.5 0.0 1.0" />
    </material>
    <material name="yelloww">
        <color rgba="1.0 1.0 0.0 1.0" />
    </material>
    <material name="greenw">
        <color rgba="0.0 1.0 0.0 1.0" />
    </material>
    <material name="bluew">
        <color rgba="0.0 0.0 1.0 1.0" />
    </material>
    <material name="indigow">
        <color rgba="0.3 0.3 0.6 1.0" />
    </material>
    <material name="violetw">
        <color rgba="0.6 0.0 1.0 1.0" />
    </material>
    <material name="blackw">
        <color rgba="0.0 0.0 0.0 1.0" />
    </material>
    <material name="darkolivew">
        <color rgba="0.3 0.3 0.25 1.0" />
    </material>
    <!--LinkDescription-->
    <link name="link_0">
        <visual>
            <geometry>
                <mesh filename="package://tm_description/meshes/tm12/visual/tm12-base.obj" />
            </geometry>
            <material name="none" />
        </visual>
        <collision>
            <geometry>
                <mesh filename="package://tm_description/meshes/tm12/collision/tm12-base_c.stl" />
            </geometry>
        </collision>
        <inertial>
            <mass value="1.0" />
            <origin rpy="0.000000 0.000000 0.000000" xyz="0.000000 0.000000 0.000000" />
            <inertia ixx="0.00110833289" ixy="0.0" ixz="0.0" iyy="0.00110833289" iyz="0.0" izz="0.0018" />
        </inertial>
    </link>
    <joint name="shoulder_1_joint" type="revolute">
        <parent link="link_0" />
        <child link="link_1" />
        <origin rpy="0.000000 -0.000000 0.000000" xyz="0.000000 0.000000 0.165200" />
        <axis xyz="0 0 1" />
        <!--limit-->
        <limit effort="353" lower="-4.71238898038469" upper="4.71238898038469" velocity="2.0943951023931953" />
        <dynamics damping="0.0" friction="0.0" />
    </joint>
    <link name="link_1">
        <visual>
            <geometry>
                <mesh filename="package://tm_description/meshes/tm12/visual/tmr_750w_01.obj" />
            </geometry>
            <material name="none" />
        </visual>
        <collision>
            <geometry>
                <mesh filename="package://tm_description/meshes/tm12/collision/tmr_750w_01_c.stl" />
            </geometry>
        </collision>
        <inertial>
            <origin rpy="0.000000 0.000000 0.000000" xyz="0.000000 0.000000 0.000000" />
            <mass value="7.6" />
            <inertia ixx="0.020289334" ixy="0.000000" ixz="0.000000" iyy="0.020289334" iyz="0.000000" izz="0.021396270999999998" />
        </inertial>
    </link>
    <joint name="shoulder_2_joint" type="revolute">
        <parent link="link_1" />
        <child link="link_2" />
        <origin rpy="-1.570796 -1.570796 0.000000" xyz="0.000000 0.000000 0.000000" />
        <axis xyz="0 0 1" />
        <!--limit-->
        <limit effort="353" lower="-3.141592653589793" upper="3.141592653589793" velocity="2.0943951023931953" />
        <dynamics damping="0.0" friction="0.0" />
    </joint>
    <link name="link_2">
        <visual>
            <geometry>
                <mesh filename="package://tm_description/meshes/tm14/visual/tm14_arm1.obj" />
            </geometry>
            <material name="none" />
        </visual>
        <collision>
            <geometry>
                <mesh filename="package://tm_description/meshes/tm14/collision/tm14_arm1_c.stl" />
            </geometry>
        </collision>
        <inertial>
            <origin rpy="0.000000 0.000000 0.000000" xyz="0.000000 0.000000 0.000000" />
            <mass value="14.0239" />
            <inertia ixx="0.071505715" ixy="0.000000" ixz="0.000000" iyy="1.1758788999999998" iyz="0.000000" izz="1.2033932999999999" />
        </inertial>
    </link>
    <joint name="elbow_joint" type="revolute">
        <parent link="link_2" />
        <child link="link_3" />
        <origin rpy="0.000000 -0.000000 0.000000" xyz="0.536100 0.000000 0.000000" />
        <axis xyz="0 0 1" />
        <!--limit-->
        <limit effort="157" lower="-2.8448866807507573" upper="2.8448866807507573" velocity="3.141592653589793" />
        <dynamics damping="0.0" friction="0.0" />
    </joint>
    <link name="link_3">
        <visual>
            <geometry>
                <mesh filename="package://tm_description/meshes/tm14/visual/tm14_arm2.obj" />
            </geometry>
            <material name="none" />
        </visual>
        <collision>
            <geometry>
                <mesh filename="package://tm_description/meshes/tm14/collision/tm14_arm2_c.stl" />
            </geometry>
        </collision>
        <inertial>
            <origin rpy="0.000000 0.000000 0.000000" xyz="0.000000 0.000000 0.000000" />
            <mass value="3.3577" />
            <inertia ixx="0.009755469" ixy="0.000000" ixz="0.000000" iyy="0.16334719" iyz="0.000000" izz="0.16656678" />
        </inertial>
    </link>
    <joint name="wrist_1_joint" type="revolute">
        <parent link="link_3" />
        <child link="link_4" />
        <origin rpy="0.000000 -0.000000 1.570796" xyz="0.457900 0.000000 -0.156300" />
        <axis xyz="0 0 1" />
        <!--limit-->
        <limit effort="54" lower="-3.141592653589793" upper="3.141592653589793" velocity="2.6179938779914944" />
        <dynamics damping="0.0" friction="0.0" />
    </joint>
    <link name="link_4">
        <visual>
            <geometry>
                <mesh filename="package://tm_description/meshes/tm5-900/visual/tmr_100w_01.obj" />
            </geometry>
            <material name="none" />
        </visual>
        <collision>
            <geometry>
                <mesh filename="package://tm_description/meshes/tm5-900/collision/tmr_100w_01_c.stl" />
            </geometry>
        </collision>
        <inertial>
            <origin rpy="0.000000 0.000000 0.000000" xyz="0.000000 0.000000 0.000000" />
            <mass value="1.576" />
            <inertia ixx="0.002058405" ixy="0.000000" ixz="0.000000" iyy="0.0025630790000000002" iyz="0.000000" izz="0.00264321" />
        </inertial>
    </link>
    <joint name="wrist_2_joint" type="revolute">
        <parent link="link_4" />
        <child link="link_5" />
        <origin rpy="1.570796 -0.000000 0.000000" xyz="0.000000 -0.106000 0.000000" />
        <axis xyz="0 0 1" />
        <!--limit-->
        <limit effort="54" lower="-3.141592653589793" upper="3.141592653589793" velocity="2.6179938779914944" />
        <dynamics damping="0.0" friction="0.0" />
    </joint>
    <link name="link_5">
        <visual>
            <geometry>
                <mesh filename="package://tm_description/meshes/tm5-900/visual/tmr_100w_02.obj" />
            </geometry>
            <material name="none" />
        </visual>
        <collision>
            <geometry>
                <mesh filename="package://tm_description/meshes/tm5-900/collision/tmr_100w_02_c.stl" />
            </geometry>
        </collision>
        <inertial>
            <origin rpy="0.000000 0.000000 0.000000" xyz="0.000000 0.000000 0.000000" />
            <mass value="1.576" />
            <inertia ixx="0.002058405" ixy="0.000000" ixz="0.000000" iyy="0.0025630790000000002" iyz="0.000000" izz="0.00264321" />
        </inertial>
    </link>
    <joint name="wrist_3_joint" type="revolute">
        <parent link="link_5" />
        <child link="link_6" />
        <origin rpy="1.570796 -0.000000 0.000000" xyz="0.000000 -0.113150 0.000000" />
        <axis xyz="0 0 1" />
        <!--limit-->
        <limit effort="54" lower="-4.71238898038469" upper="4.71238898038469" velocity="3.141592653589793" />
        <dynamics damping="0.0" friction="0.0" />
    </joint>
    <link name="link_6">
        <visual>
            <geometry>
                <mesh filename="package://tm_description/meshes/tm5-900/visual/tmr_iox.obj" />
            </geometry>
            <material name="none" />
        </visual>
        <collision>
            <geometry>
                <mesh filename="package://tm_description/meshes/tm5-900/collision/tmr_iox_c.stl" />
            </geometry>
        </collision>
        <inertial>
            <origin rpy="0.000000 0.000000 0.000000" xyz="0.000000 0.000000 0.000000" />
            <mass value="0.31" />
            <inertia ixx="0.000226642" ixy="0.000000" ixz="0.000000" iyy="0.000226642" iyz="0.000000" izz="0.000286595" />
        </inertial>
    </link>
    <joint name="flange_fixed_joint" type="fixed">
        <parent link="link_6" />
        <child link="flange_link" />
        <origin rpy="0.000000 0.000000 0.000000" xyz="0.000000 0.000000 0.000000" />
    </joint>
    <link name="flange_link" />
    <link name="base" />
    <joint name="base_fixed_joint" type="fixed">
        <parent link="base" />
        <child link="link_0" />
        <origin rpy="0.000000 0.000000 0.000000" xyz="0.000000 0.000000 0.000000" />
    </joint>
    <link name="tool0" />
    <joint name="flange_link-tool0" type="fixed">
        <parent link="flange_link" />
        <child link="tool0" />
        <origin rpy="0.000000 0.000000 0.000000" xyz="0.000000 0.000000 0.000000" />
    </joint>
    <!--LinkDescription-->
    <joint name="world_joint" type="fixed">
        <parent link="base_link" />
        <child link="base" />
        <origin rpy="0 0 0" xyz="0.3 0 0.27" />
    </joint>
</robot>

